<?xml version="1.0"?>
<robot name="pavlov_mini" xmlns:xacro="http://ros.org/wiki/xacro">

  <!-- <xacro:arg name="is_ignition" default="true"/> -->

  <!-- <xacro:include filename="$(find pavlov_description)/urdf/pavlov_mini_ros2_control.xacro" /> -->

  <link name="base_link">
    <visual>
      <geometry>
        <mesh filename= "package://pavlov_description/meshes/base.dae"/>
      </geometry>
    </visual>
    <inertial>
      <origin xyz="-0.000492 0.000002 0.014305" rpy="0 0 0"/>
      <mass value="2.05964"/>
      <inertia
        ixx="0.00372"
        iyy="0.00868"
        izz="0.00992"
        ixy="0.0"
        ixz="0.0"
        iyz="0.0"/>
    </inertial>
    <collision>
      <origin xyz="0.000 0.000 0.015" rpy ="0.000 0.000 0.000"/>
      <geometry>
        <box size="0.260 0.160 0.090"/>
      </geometry>
    </collision>
  </link>

  <link name="lidar_link">
    <visual>
      <geometry>
        <mesh filename= "package://pavlov_description/meshes/lidar.dae"/>
      </geometry>
    </visual>
    <inertial>
      <origin xyz="0.000 0.000 0.000" rpy ="0.000 0.000 0.000"/>
      <mass value="0.050"/>
      <inertia
        ixx="0.00092" ixy="0.00000" ixz="0.00001"
        iyy="0.00094" iyz="0.00000"
        izz="0.00093"/>
    </inertial>
    <collision>
      <origin xyz="0.010 0.000 -0.015" rpy ="0.000 0.000 0.000"/>
      <geometry>
        <box size="0.080 0.060 0.050"/>
      </geometry>
    </collision>

  </link>

  <link name="hip_fl_ref">
    <visual>
      <geometry>
        <box size="0.002 0.002 0.002"/>
      </geometry>
    </visual>
    <inertial>
      <origin xyz="0.000 0.000 0.000" rpy ="0.000 0.000 0.000"/>
      <mass value="0.001"/>  <!-- 0.000 yerine -->
      <inertia
        ixx="0.000001" ixy="0.00000" ixz="0.00000"
        iyy="0.000001" iyz="0.00000"
        izz="0.000001"/>
    </inertial>
    <collision>
      <origin xyz="0.000 0.000 0.000" rpy ="0.000 0.000 0.000"/>
      <geometry>
        <box size="0.002 0.002 0.002"/>
      </geometry>
    </collision>
  </link>

  <link name="hip_fr_ref">
    <visual>
      <geometry>
        <box size="0.002 0.002 0.002"/>
      </geometry>
    </visual>
    <inertial>
      <origin xyz="0.000 0.000 0.000" rpy ="0.000 0.000 0.000"/>
      <mass value="0.001"/> 
      <inertia
        ixx="0.000001" ixy="0.00000" ixz="0.00000"
        iyy="0.000001" iyz="0.00000"
        izz="0.000001"/>
    </inertial>
    <collision>
      <origin xyz="0.000 0.000 0.000" rpy ="0.000 0.000 0.000"/>
      <geometry>
        <box size="0.002 0.002 0.002"/>
      </geometry>
    </collision>
  </link>

  <link name="hip_bl_ref">
    <visual>
      <geometry>
        <box size="0.002 0.002 0.002"/>
      </geometry>
    </visual>
    <inertial>
      <origin xyz="0.000 0.000 0.000" rpy ="0.000 0.000 0.000"/>
      <mass value="0.001"/> 
      <inertia
        ixx="0.000001" ixy="0.00000" ixz="0.00000"
        iyy="0.000001" iyz="0.00000"
        izz="0.000001"/>
    </inertial>
    <collision>
      <origin xyz="0.000 0.000 0.000" rpy ="0.000 0.000 0.000"/>
      <geometry>
        <box size="0.002 0.002 0.002"/>
      </geometry>
    </collision>
  </link>

  <link name="hip_br_ref">
    <visual>
      <geometry>
        <box size="0.002 0.002 0.002"/>
      </geometry>
    </visual>
    <inertial>
      <origin xyz="0.000 0.000 0.000" rpy ="0.000 0.000 0.000"/>
      <mass value="0.001"/> 
      <inertia
        ixx="0.000001" ixy="0.00000" ixz="0.00000"
        iyy="0.000001" iyz="0.00000"
        izz="0.000001"/>
    </inertial>
    <collision>
      <origin xyz="0.000 0.000 0.000" rpy ="0.000 0.000 0.000"/>
      <geometry>
        <box size="0.002 0.002 0.002"/>
      </geometry>
    </collision>
  </link>

  <link name="hip_fl_link">
    <visual>
      <geometry>
        <mesh filename= "package://pavlov_description/meshes/hip_fl.dae"/>
      </geometry>
    </visual>
    <inertial>
      <origin xyz="-0.002211 0.000093 0.004829" rpy="0 0 0"/>
      <mass value="0.04528"/>
      <inertia
        ixx="0.00002615"
        iyy="0.00002831"
        izz="0.00002071"
        ixy="0.0"
        ixz="0.0"
        iyz="0.0"/>
    </inertial>
    <collision>
      <origin xyz="-0.005 -0.005 0.005" rpy ="0.000 0.000 0.000"/>
      <geometry>
        <box size="0.050 0.050 0.070"/>
      </geometry>
    </collision>
  </link>

  <link name="hip_fr_link">
    <visual>
      <geometry>
        <mesh filename= "package://pavlov_description/meshes/hip_fr.dae"/>
      </geometry>
    </visual>
    <inertial>
        <origin xyz="-0.002212 -0.000095 0.004830" rpy="0 0 0"/>
        <mass value="0.04528"/>
        <inertia
          ixx="0.00002615"
          iyy="0.00002831"
          izz="0.00002071"
          ixy="0.0"
          ixz="0.0"
          iyz="0.0"/>
    </inertial>
    <collision>
      <origin xyz="-0.005 0.005 0.005" rpy ="0.000 0.000 0.000"/>
      <geometry>
        <box size="0.050 0.050 0.070"/>
      </geometry>
    </collision>
  </link>

  <link name="hip_bl_link">
    <visual>
      <geometry>
        <mesh filename= "package://pavlov_description/meshes/hip_bl.dae"/>
      </geometry>
    </visual>
    <inertial>
      <origin xyz="0.002212 0.000095 0.004830" rpy="0 0 0"/>
      <mass value="0.04528"/>
      <inertia
        ixx="0.00002615"
        iyy="0.00002831"
        izz="0.00002071"
        ixy="0.0"
        ixz="0.0"
        iyz="0.0"/>
    </inertial>
    <collision>
      <origin xyz="0.005 -0.005 0.005" rpy ="0.000 0.000 0.000"/>
      <geometry>
        <box size="0.050 0.050 0.070"/>
      </geometry>
    </collision>
  </link>

  <link name="hip_br_link">
    <visual>
      <geometry>
        <mesh filename= "package://pavlov_description/meshes/hip_br.dae"/>
      </geometry>
    </visual>
    <inertial>
      <origin xyz="0.002211 -0.000093 0.004829" rpy="0 0 0"/>
      <mass value="0.04528"/>
      <inertia
        ixx="0.00002615"
        iyy="0.00002831"
        izz="0.00002071"
        ixy="0.0"
        ixz="0.0"
        iyz="0.0"/>
    </inertial>
    <collision>
      <origin xyz="0.005 0.005 0.005" rpy ="0.000 0.000 0.000"/>
      <geometry>
        <box size="0.050 0.050 0.070"/>
      </geometry>
    </collision>
  </link>

  <link name="femur_fl_link">
    <visual>
      <geometry>
        <mesh filename= "package://pavlov_description/meshes/femur_fl.dae"/>
      </geometry>
    </visual>
    <inertial>
      <origin xyz="-0.000176 0.010059 -0.024478" rpy="0 0 0"/>
      <mass value="0.550811"/>
      <inertia
        ixx="0.00109482916"
        iyy="0.00092023806"
        izz="0.00034947930"
        ixy="0.0"
        ixz="0.0"
        iyz="0.0"/>
    </inertial>
    <collision>
      <origin xyz="0.000 0.015 -0.045" rpy ="0.000 0.000 0.000"/>
      <geometry>
        <box size="0.040 0.070 0.130"/>
      </geometry>
    </collision>
  </link>

  <link name="femur_fr_link">
    <visual>
      <geometry>
        <mesh filename= "package://pavlov_description/meshes/femur_fr.dae"/>
      </geometry>
    </visual>
    <inertial>
      <origin xyz="-0.000176 -0.010119 -0.024478" rpy="0 0 0"/>
      <mass value="0.096623"/>
      <inertia
        ixx="0.00019204"
        iyy="0.00016143"
        izz="0.00006129"
        ixy="0.0"
        ixz="0.0"
        iyz="0.0"/>
    </inertial>
    <collision>
      <origin xyz="0.000 -0.015 -0.045" rpy ="0.000 0.000 0.000"/>
      <geometry>
        <box size="0.040 0.070 0.130"/>
      </geometry>
    </collision>
  </link>

  <link name="femur_bl_link">
    <visual>
      <geometry>
        <mesh filename= "package://pavlov_description/meshes/femur_bl.dae"/>
      </geometry>
    </visual>
    <inertial>
      <origin xyz="-0.000176 0.010059 -0.024478" rpy="0 0 0"/>
      <mass value="0.550811"/>
      <inertia
        ixx="0.00109482916"
        iyy="0.00092023806"
        izz="0.00034947930"
        ixy="0.0"
        ixz="0.0"
        iyz="0.0"/>
    </inertial>
    <collision>
      <origin xyz="0.000 0.015 -0.045" rpy ="0.000 0.000 0.000"/>
      <geometry>
        <box size="0.040 0.070 0.130"/>
      </geometry>
    </collision>
  </link>

  <link name="femur_br_link">
    <visual>
      <geometry>
        <mesh filename= "package://pavlov_description/meshes/femur_br.dae"/>
      </geometry>
    </visual>
    <inertial>
      <origin xyz="-0.000176 -0.010119 -0.024478" rpy="0 0 0"/>
      <mass value="0.096623"/>
      <inertia
        ixx="0.00019204"
        iyy="0.00016143"
        izz="0.00006129"
        ixy="0.0"
        ixz="0.0"
        iyz="0.0"/>
    </inertial>
    <collision>
      <origin xyz="0.000 -0.015 -0.045" rpy ="0.000 0.000 0.000"/>
      <geometry>
        <box size="0.040 0.070 0.130"/>
      </geometry>
    </collision>
  </link>

  <link name="tibia_fl_link">
    <visual>
      <geometry>
        <mesh filename= "package://pavlov_description/meshes/tibia_fl.dae"/>
      </geometry>
    </visual>
    <inertial>
      <origin xyz="0.000 0.000 0.000" rpy ="0.000 0.000 0.000"/>
      <mass value="0.034"/>
      <inertia
        ixx="0.00159" ixy="0.00000" ixz="-0.00001"
        iyy="0.00159" iyz="0.00000"
        izz="0.00147"/>
    </inertial>
    <collision>
      <origin xyz="0.000 0.000 -0.050" rpy="0.000 0.000 0.000"/>
      <geometry>
        <box size="0.030 0.030 0.100"/>
      </geometry>
    </collision>
  </link>

  <link name="tibia_fr_link">
    <visual>
      <geometry>
        <mesh filename= "package://pavlov_description/meshes/tibia_fr.dae"/>
      </geometry>
    </visual>
    <inertial>
      <origin xyz="0.000 0.000 0.000" rpy ="0.000 0.000 0.000"/>
      <mass value="0.034"/>
      <inertia
        ixx="0.00159" ixy="0.00000" ixz="-0.00001"
        iyy="0.00159" iyz="0.00000"
        izz="0.00147"/>
    </inertial>
    <collision>
      <origin xyz="0.000 0.000 -0.050" rpy="0.000 0.000 0.000"/>
      <geometry>
        <box size="0.030 0.030 0.100"/>
      </geometry>
    </collision>
  </link>

  <link name="tibia_bl_link">
    <visual>
      <geometry>
        <mesh filename= "package://pavlov_description/meshes/tibia_bl.dae"/>
      </geometry>
    </visual>
    <inertial>
      <origin xyz="0.000 0.000 0.000" rpy ="0.000 0.000 0.000"/>
      <mass value="0.034"/>
      <inertia
        ixx="0.00159" ixy="0.00000" ixz="-0.00001"
        iyy="0.00159" iyz="0.00000"
        izz="0.00147"/>
    </inertial>
    <collision>
      <origin xyz="0.000 0.000 -0.050" rpy="0.000 0.000 0.000"/>
      <geometry>
        <box size="0.030 0.030 0.100"/>
      </geometry>
    </collision>
  </link>

  <link name="tibia_br_link">
    <visual>
      <geometry>
        <mesh filename= "package://pavlov_description/meshes/tibia_br.dae"/>
      </geometry>
    </visual>
    <inertial>
      <origin xyz="0.000 0.000 0.000" rpy ="0.000 0.000 0.000"/>
      <mass value="0.034"/>
      <inertia
        ixx="0.00159" ixy="0.00000" ixz="-0.00001"
        iyy="0.00159" iyz="0.00000"
        izz="0.00147"/>
    </inertial>
    <collision>
      <origin xyz="0.000 0.000 -0.050" rpy="0.000 0.000 0.000"/>
      <geometry>
        <box size="0.030 0.030 0.100"/>
      </geometry>
    </collision>
  </link>

  <link name="feet_fl">
    <visual>
      <geometry>
        <sphere radius="0.001"/>
      </geometry>
    </visual>
    <inertial>
      <origin xyz="0.000 0.000 0.000" rpy ="0.000 0.000 0.000"/>
      <mass value="0.010"/>
      <inertia
        ixx="0.00009" ixy="0.00000" ixz="0.00000"
        iyy="0.00009" iyz="0.00000"
        izz="0.00009"/>
    </inertial>
    <collision>
      <origin xyz="0.000 0.000 0.000" rpy ="0.000 0.000 0.000"/>
      <geometry>
        <box size="0.011 0.011 0.011"/>
      </geometry>
    </collision>
  </link>

  <link name="feet_fr">
    <visual>
      <geometry>
        <sphere radius="0.001"/>
      </geometry>
    </visual>
    <inertial>
      <origin xyz="0.000 0.000 0.000" rpy ="0.000 0.000 0.000"/>
      <mass value="0.010"/>
      <inertia
        ixx="0.00009" ixy="0.00000" ixz="0.00000"
        iyy="0.00009" iyz="0.00000"
        izz="0.00009"/>
    </inertial>
    <collision>
      <origin xyz="0.000 0.000 0.000" rpy ="0.000 0.000 0.000"/>
      <geometry>
        <box size="0.011 0.011 0.011"/>
      </geometry>
    </collision>
  </link>

  <link name="feet_bl">
    <visual>
      <geometry>
        <sphere radius="0.001"/>
      </geometry>
    </visual>
    <inertial>
      <origin xyz="0.000 0.000 0.000" rpy ="0.000 0.000 0.000"/>
      <mass value="0.010"/>
      <inertia
        ixx="0.00009" ixy="0.00000" ixz="0.00000"
        iyy="0.00009" iyz="0.00000"
        izz="0.00009"/>
    </inertial>
    <collision>
      <origin xyz="0.000 0.000 0.000" rpy ="0.000 0.000 0.000"/>
      <geometry>
        <box size="0.011 0.011 0.011"/>
      </geometry>
    </collision>
  </link>

  <link name="feet_br">
    <visual>
      <geometry>
        <sphere radius="0.001"/>
      </geometry>
    </visual>
    <inertial>
      <origin xyz="0.000 0.000 0.000" rpy ="0.000 0.000 0.000"/>
      <mass value="0.010"/>
      <inertia
        ixx="0.00009" ixy="0.00000" ixz="0.00000"
        iyy="0.00009" iyz="0.00000"
        izz="0.00009"/>
    </inertial>
    <collision>
      <origin xyz="0.000 0.000 0.000" rpy ="0.000 0.000 0.000"/>
      <geometry>
        <box size="0.011 0.011 0.011"/>
      </geometry>
    </collision>
  </link>

  <!-- JOINTS -->

  <joint name="lidar" type="fixed" dont_collapse="true">
    <parent link="base_link"/>
    <child  link="lidar_link"/>
    <origin xyz="0.04312 0.00000 0.08341"/>
  </joint>

  <joint name="fl_ref" type="fixed" dont_collapse="true">
    <parent link="base_link"/>
    <child  link="hip_fl_ref"/>
    <origin xyz="0.09170 0.05355 -0.00279"/>
  </joint>

  <joint name="fr_ref" type="fixed" dont_collapse="true">
    <parent link="base_link"/>
    <child  link="hip_fr_ref"/>
    <origin xyz="0.09170 -0.05355 -0.00279"/>
  </joint>

  <joint name="bl_ref" type="fixed" dont_collapse="true">
    <parent link="base_link"/>
    <child  link="hip_bl_ref"/>
    <origin xyz="-0.09170 0.05355 -0.00279"/>
  </joint>

  <joint name="br_ref" type="fixed" dont_collapse="true">
    <parent link="base_link"/>
    <child  link="hip_br_ref"/>
    <origin xyz="-0.09170 -0.05355 -0.00279"/>
  </joint>

  <joint name="hip1_fl" type="revolute">
    <axis xyz="1.000 0.000 0.000"/>
    <limit effort="80.00000" lower="-0.78540" upper="1.57080" velocity="1.04720"/>
    <parent link="hip_fl_ref"/>
    <child  link="hip_fl_link"/>
    <origin xyz="0.00000 0.00000 0.00000"/>
  </joint>

  <joint name="hip1_fr" type="revolute">
    <axis xyz="1.000 0.000 0.000"/>
    <limit effort="80.00000" lower="-0.78540" upper="1.57080" velocity="1.04720"/>
    <parent link="hip_fr_ref"/>
    <child  link="hip_fr_link"/>
    <origin xyz="0.00000 0.00000 0.00000"/>
  </joint>

  <joint name="hip1_bl" type="revolute">
    <axis xyz="1.000 0.000 0.000"/>
    <limit effort="80.00000" lower="-0.78540" upper="1.57080" velocity="1.04720"/>
    <parent link="hip_bl_ref"/>
    <child  link="hip_bl_link"/>
    <origin xyz="0.00000 0.00000 0.00000"/>
  </joint>

  <joint name="hip1_br" type="revolute">
    <axis xyz="1.000 0.000 0.000"/>
    <limit effort="80.00000" lower="-0.78540" upper="1.57080" velocity="1.04720"/>
    <parent link="hip_br_ref"/>
    <child  link="hip_br_link"/>
    <origin xyz="0.00000 0.00000 0.00000"/>
  </joint>

  <joint name="hip2_fl" type="revolute">
    <axis xyz="0.000 1.000 0.000"/>
    <limit effort="80.00000" lower="0.00000" upper="2.35619" velocity="1.04720"/>
    <parent link="hip_fl_link"/>
    <child  link="femur_fl_link"/>
    <origin xyz="0.00000 0.03559 0.00000"/>
  </joint>

  <joint name="hip2_fr" type="revolute">
    <axis xyz="0.000 1.000 0.000"/>
    <limit effort="80.00000" lower="0.00000" upper="2.35619" velocity="1.04720"/>
    <parent link="hip_fr_link"/>
    <child  link="femur_fr_link"/>
    <origin xyz="0.00000 -0.03559 0.00000"/>
  </joint>

  <joint name="hip2_bl" type="revolute">
    <axis xyz="0.000 1.000 0.000"/>
    <limit effort="80.00000" lower="0.00000" upper="2.35619" velocity="1.04720"/>
    <parent link="hip_bl_link"/>
    <child  link="femur_bl_link"/>
    <origin xyz="0.00000 0.03559 0.00000" />
  </joint>

  <joint name="hip2_br" type="revolute">
    <axis xyz="0.000 1.000 0.000"/>
    <limit effort="80.00000" lower="0.00000" upper="2.35619" velocity="1.04720"/>
    <parent link="hip_br_link"/>
    <child  link="femur_br_link"/>
    <origin xyz="0.00000 -0.03559 0.00000"/>
  </joint>

  <joint name="knee_fl" type="revolute">
    <axis xyz="0.000 1.000 0.000"/>
    <limit effort="80.00000" lower="-2.35619" upper="-0.22360" velocity="1.04720"/>
    <parent link="femur_fl_link"/>
    <child  link="tibia_fl_link"/>
    <origin xyz="0.00000 0.01071 -0.09996" rpy="0.000 0 0.000"/>
  </joint>

  <joint name="knee_fr" type="revolute">
    <axis xyz="0.000 1.000 0.000"/>
    <limit effort="80.00000" lower="-2.35619" upper="-0.22360" velocity="1.04720"/>
    <parent link="femur_fr_link"/>
    <child  link="tibia_fr_link"/>
    <origin xyz="0.00000 -0.01071 -0.09996" rpy="0.000 0 0.000"/>
  </joint>

  <joint name="knee_bl" type="revolute">
    <axis xyz="0.000 1.000 0.000"/>
    <limit effort="80.00000" lower="-2.35619" upper="-0.22360" velocity="1.04720"/>
    <parent link="femur_bl_link"/>
    <child  link="tibia_bl_link"/>
    <origin xyz="0.00000 0.01071 -0.09996" rpy="0.000 0 0.000"/>
  </joint>

  <joint name="knee_br" type="revolute">
    <axis xyz="0.000 1.000 0.000"/>
    <limit effort="80.00000" lower="-2.35619" upper="-0.22360" velocity="1.04720"/>
    <parent link="femur_br_link"/>
    <child  link="tibia_br_link"/>
    <origin xyz="0.00000 -0.01071 -0.09996" rpy="0.000 0 0.000"/>
  </joint>

  <joint name="feet_fl_ref" type="fixed" dont_collapse="true">
    <parent link="tibia_fl_link"/>
    <child  link="feet_fl"/>
    <origin xyz="0.00000 -0.00834 -0.10000"/>
  </joint>

  <joint name="feet_fr_ref" type="fixed" dont_collapse="true">
    <parent link="tibia_fr_link"/>
    <child  link="feet_fr"/>
    <origin xyz="0.00000 0.00834 -0.10000"/>
  </joint>

  <joint name="feet_bl_ref" type="fixed" dont_collapse="true">
    <parent link="tibia_bl_link"/>
    <child  link="feet_bl"/>
    <origin xyz="0.00000 -0.00834 -0.10000"/>
  </joint>

  <joint name="feet_br_ref" type="fixed" dont_collapse="true">
    <parent link="tibia_br_link"/>
    <child  link="feet_br"/>
    <origin xyz="0.00000 0.00834 -0.10000"/>
  </joint>

  <!--
  <gazebo>
    <plugin name="ignition::gazebo::systems::IgnitionRos2Control"
            filename="libign_ros2_control-system.so">
      <robot_param>robot_description</robot_param>

      <parameters>
        $(find pavlov_control)/config/ros2_controllers.yaml
      </parameters>

    </plugin>
  </gazebo>
-->

</robot>
